Workbook

Sheet Indice
A1: Base de datos — Smith, Van Ness & Abbott, Introducción a la Termodinámica en Ingeniería Química, 7a ed.
A3: Contenido
A4: B1_Propiedades — Tabla B.1: masa molar, ω, Tc, Pc, Zc, Vc, Tn (89 especies)
A5: C1_Gases — Tabla C.1: Cp^ig/R = A + B·T + C·T² + D·T⁻², T en K, 298 → Tmáx (48 especies)
A6: C2_Solidos — Tabla C.2: Cp/R = A + B·T + D·T⁻² (21 especies)
A7: C3_Liquidos — Tabla C.3: Cp/R = A + B·T + C·T², 273.15–373.15 K (15 especies)
A8: C4_Formacion — Tabla C.4: ΔH°f298 y ΔG°f298 en J/mol, estado estándar (g)/(l)/(s)/(ac) a 298.15 K y 1 bar (77 filas)
A9: BD_Gases — Maestro para equilibrio químico: por especie gaseosa, Hf, Gf y A, B, C, D REALES (ya multiplicados) vía INDEX/MATCH a C1 y C4
A10: Buscar — Escribe una fórmula (celda amarilla) y obtienes todas sus propiedades
A12: Convenciones
A13: Amarillo = encabezados / celdas de entrada. Azul oscuro = constante transcrita del libro. Negro = fórmula.
A14: En C1–C3 las columnas 10³B, 10⁶C, 10⁻⁵D son EXACTAMENTE como el libro; las columnas B, C, D (reales) ya llevan el factor: B = 10³B × 1e-3, C = 10⁶C × 1e-6, D = 10⁻⁵D × 1e5.
... A22: Generado: 2026-09-22.

Sheet B1_Propiedades
A1: Tabla B.1: Propiedades características de especies puras
A2: Masa molar en g/mol; Tc, Tn en K; Pc en bar; Vc en cm³/mol. Fuente: DIPPR Project 801 (según SVA).
A4: Especie (EN) | B4: Masa molar | C4: ω | D4: Tc /K | E4: Pc /bar | F4: Zc | G4: Vc /cm³·mol⁻¹ | H4: Tn /K
A5: Methane | B5: 16.043 | C5: 0.012 | D5: 190.6 | E5: 45.99 | F5: 0.286 | G5: 98.6 | H5: 111.4
A6: Ethane | B6: 30.07 | C6: 0.1 | D6: 305.3 | E6: 48.72 | F6: 0.279 | G6: 145.5 | H6: 184.6
A7: Propane | B7: 44.097 | C7: 0.152 | D7: 369.8 | E7: 42.48 | F7: 0.276 | G7: 200 | H7: 231.1
A8: n-Butane | B8: 58.123 | C8: 0.2 | D8: 425.1 | E8: 37.96 | F8: 0.274 | G8: 255 | H8: 272.7
A9: n-Pentane | B9: 72.15 | C9: 0.252 | D9: 469.7 | E9: 33.7 | F9: 0.27 | G9: 313 | H9: 309.2
A10: n-Hexane | B10: 86.177 | C10: 0.301 | D10: 507.6 | E10: 30.25 | F10: 0.266 | G10: 371 | H10: 341.9
A11: n-Heptane | B11: 100.204 | C11: 0.35 | D11: 540.2 | E11: 27.4 | F11: 0.261 | G11: 428 | H11: 371.6
A12: n-Octane | B12: 114.231 | C12: 0.4 | D12: 568.7 | E12: 24.9 | F12: 0.256 | G12: 486 | H12: 398.8
A13: n-Nonane | B13: 128.258 | C13: 0.444 | D13: 594.6 | E13: 22.9 | F13: 0.252 | G13: 544 | H13: 424
A14: n-Decane | B14: 142.285 | C14: 0.492 | D14: 617.7 | E14: 21.1 | F14: 0.247 | G14: 600 | H14: 447.3
A15: Isobutane | B15: 58.123 | C15: 0.181 | D15: 408.1 | E15: 36.48 | F15: 0.282 | G15: 262.7 | H15: 261.4
A16: Isooctane | B16: 114.231 | C16: 0.302 | D16: 544 | E16: 25.68 | F16: 0.266 | G16: 468 | H16: 372.4
... A77: Nitrogen | B77: 28.014 | C77: 0.038 | D77: 126.2 | E77: 34 | F77: 0.289 | G77: 89.2 | H77: 77.3
A78: Air | B78: 28.851 | C78: 0.035 | D78: 132.2 | E78: 37.45 | F78: 0.289 | G78: 84.8
A79: Chlorine | B79: 70.905 | C79: 0.069 | D79: 417.2 | E79: 77.1 | F79: 0.265 | G79: 124 | H79: 239.1
A80: Carbon monoxide | B80: 28.01 | C80: 0.048 | D80: 132.9 | E80: 34.99 | F80: 0.299 | G80: 93.4 | H80: 81.7
A81: Carbon dioxide | B81: 44.01 | C81: 0.224 | D81: 304.2 | E81: 73.83 | F81: 0.274 | G81: 94
A82: Carbon disulfide | B82: 76.143 | C82: 0.111 | D82: 552 | E82: 79 | F82: 0.275 | G82: 160 | H82: 319.4
A83: Hydrogen sulfide | B83: 34.082 | C83: 0.094 | D83: 373.5 | E83: 89.63 | F83: 0.284 | G83: 98.5 | H83: 212.8
A84: Sulfur dioxide | B84: 64.065 | C84: 0.245 | D84: 430.8 | E84: 78.84 | F84: 0.269 | G84: 122 | H84: 263.1
A85: Sulfur trioxide | B85: 80.064 | C85: 0.424 | D85: 490.9 | E85: 82.1 | F85: 0.255 | G85: 127 | H85: 317.9
A86: Nitric oxide (NO) | B86: 30.006 | C86: 0.583 | D86: 180.2 | E86: 64.8 | F86: 0.251 | G86: 58 | H86: 121.4
A87: Nitrous oxide (N2O) | B87: 44.013 | C87: 0.141 | D87: 309.6 | E87: 72.45 | F87: 0.274 | G87: 97.4 | H87: 184.7
A88: Hydrogen chloride | B88: 36.461 | C88: 0.132 | D88: 324.7 | E88: 83.1 | F88: 0.249 | G88: 81 | H88: 188.2
A89: Hydrogen cyanide | B89: 27.026 | C89: 0.41 | D89: 456.7 | E89: 53.9 | F89: 0.197 | G89: 139 | H89: 298.9
A90: Water | B90: 18.015 | C90: 0.345 | D90: 647.1 | E90: 220.55 | F90: 0.229 | G90: 55.9 | H90: 373.2
A91: Ammonia | B91: 17.031 | C91: 0.253 | D91: 405.7 | E91: 112.8 | F91: 0.242 | G91: 72.5 | H91: 239.7
A92: Nitric acid | B92: 63.013 | C92: 0.714 | D92: 520 | E92: 68.9 | F92: 0.231 | G92: 145 | H92: 356.2
A93: Sulfuric acid | B93: 98.08 | D93: 924 | E93: 64 | F93: 0.147 | G93: 177 | H93: 610

Sheet C1_Gases
A1: Tabla C.1: Capacidades caloríficas de gases en el estado de gas ideal
A2: Cp^ig/R = A + B·T + C·T² + D·T⁻² T (K) de 298 a Tmáx. Cols. G–J tal como el libro; cols. K–N = coeficientes reales para usar en fórmulas.
A4: Grupo | B4: Especie | C4: Species | D4: Fórmula | E4: Tmáx /K | F4: Cp298/R | G4: A | H4: 10³ B | I4: 10⁶ C | J4: 10⁻⁵ D | K4: A (real) | L4: B (real) | M4: C (real) | N4: D (real)
A5: Parafinas | B5: Metano | C5: Methane | D5: CH4 | E5: 1500 | F5: 4.217 | G5: 1.702 | H5: 9.081 | I5: -2.164 | K5: =G5 -> 1.702 | L5: =IF(H5="",0,H5*0.001) -> 0.009081 | M5: =IF(I5="",0,I5*0.000001) -> -2.164e-06 | N5: =IF(J5="",0,J5*100000) -> 0
A6: Parafinas | B6: Etano | C6: Ethane | D6: C2H6 | E6: 1500 | F6: 6.369 | G6: 1.131 | H6: 19.225 | I6: -5.561 | K6: =G6 -> 1.131 | L6: =IF(H6="",0,H6*0.001) -> 0.019225 | M6: =IF(I6="",0,I6*0.000001) -> -5.561e-06 | N6: =IF(J6="",0,J6*100000) -> 0
A7: Parafinas | B7: Propano | C7: Propane | D7: C3H8 | E7: 1500 | F7: 9.011 | G7: 1.213 | H7: 28.785 | I7: -8.824 | K7: =G7 -> 1.213 | L7: =IF(H7="",0,H7*0.001) -> 0.028785 | M7: =IF(I7="",0,I7*0.000001) -> -8.824e-06 | N7: =IF(J7="",0,J7*100000) -> 0
A8: Parafinas | B8: n-Butano | C8: n-Butane | D8: C4H10 | E8: 1500 | F8: 11.928 | G8: 1.935 | H8: 36.915 | I8: -11.402 | K8: =G8 -> 1.935 | L8: =IF(H8="",0,H8*0.001) -> 0.036915 | M8: =IF(I8="",0,I8*0.000001) -> -1.1402e-05 | N8: =IF(J8="",0,J8*100000) -> 0
A9: Parafinas | B9: iso-Butano | C9: iso-Butane | D9: C4H10 (iso) | E9: 1500 | F9: 11.901 | G9: 1.677 | H9: 37.853 | I9: -11.945 | K9: =G9 -> 1.677 | L9: =IF(H9="",0,H9*0.001) -> 0.037853 | M9: =IF(I9="",0,I9*0.000001) -> -1.1945e-05 | N9: =IF(J9="",0,J9*100000) -> 0
A10: Parafinas | B10: n-Pentano | C10: n-Pentane | D10: C5H12 | E10: 1500 | F10: 14.731 | G10: 2.464 | H10: 45.351 | I10: -14.111 | K10: =G10 -> 2.464 | L10: =IF(H10="",0,H10*0.001) -> 0.045351 | M10: =IF(I10="",0,I10*0.000001) -> -1.4111e-05 | N10: =IF(J10="",0,J10*100000) -> 0
A11: Parafinas | B11: n-Hexano | C11: n-Hexane | D11: C6H14 | E11: 1500 | F11: 17.55 | G11: 3.025 | H11: 53.722 | I11: -16.791 | K11: =G11 -> 3.025 | L11: =IF(H11="",0,H11*0.001) -> 0.053722 | M11: =IF(I11="",0,I11*0.000001) -> -1.6791e-05 | N11: =IF(J11="",0,J11*100000) -> 0
A12: Parafinas | B12: n-Heptano | C12: n-Heptane | D12: C7H16 | E12: 1500 | F12: 20.361 | G12: 3.57 | H12: 62.127 | I12: -19.486 | K12: =G12 -> 3.57 | L12: =IF(H12="",0,H12*0.001) -> 0.062127 | M12: =IF(I12="",0,I12*0.000001) -> -1.9486e-05 | N12: =IF(J12="",0,J12*100000) -> 0
A13: Parafinas | B13: n-Octano | C13: n-Octane | D13: C8H18 | E13: 1500 | F13: 23.174 | G13: 4.108 | H13: 70.567 | I13: -22.208 | K13: =G13 -> 4.108 | L13: =IF(H13="",0,H13*0.001) -> 0.070567 | M13: =IF(I13="",0,I13*0.000001) -> -2.2208e-05 | N13: =IF(J13="",0,J13*100000) -> 0
A14: 1-Alquenos | B14: Etileno | C14: Ethylene | D14: C2H4 | E14: 1500 | F14: 5.325 | G14: 1.424 | H14: 14.394 | I14: -4.392 | K14: =G14 -> 1.424 | L14: =IF(H14="",0,H14*0.001) -> 0.014394 | M14: =IF(I14="",0,I14*0.000001) -> -4.392e-06 | N14: =IF(J14="",0,J14*100000) -> 0
A15: 1-Alquenos | B15: Propileno | C15: Propylene | D15: C3H6 | E15: 1500 | F15: 7.792 | G15: 1.637 | H15: 22.706 | I15: -6.915 | K15: =G15 -> 1.637 | L15: =IF(H15="",0,H15*0.001) -> 0.022706 | M15: =IF(I15="",0,I15*0.000001) -> -6.915e-06 | N15: =IF(J15="",0,J15*100000) -> 0
A16: 1-Alquenos | B16: 1-Buteno | C16: 1-Butene | D16: C4H8 | E16: 1500 | F16: 10.52 | G16: 1.967 | H16: 31.63 | I16: -9.873 | K16: =G16 -> 1.967 | L16: =IF(H16="",0,H16*0.001) -> 0.03163 | M16: =IF(I16="",0,I16*0.000001) -> -9.873e-06 | N16: =IF(J16="",0,J16*100000) -> 0
... A21: Orgánicos diversos | B21: Acetaldehído | C21: Acetaldehyde | D21: C2H4O | E21: 1000 | F21: 6.506 | G21: 1.693 | H21: 17.978 | I21: -6.158 | K21: =G21 -> 1.693 | L21: =IF(H21="",0,H21*0.001) -> 0.017978 | M21: =IF(I21="",0,I21*0.000001) -> -6.158e-06 | N21: =IF(J21="",0,J21*100000) -> 0
A22: Orgánicos diversos | B22: Acetileno | C22: Acetylene | D22: C2H2 | E22: 1500 | F22: 5.253 | G22: 6.132 | H22: 1.952 | J22: -1.299 | K22: =G22 -> 6.132 | L22: =IF(H22="",0,H22*0.001) -> 0.001952 | M22: =IF(I22="",0,I22*0.000001) -> 0 | N22: =IF(J22="",0,J22*100000) -> -129900
A23: Orgánicos diversos | B23: Benceno | C23: Benzene | D23: C6H6 | E23: 1500 | F23: 10.259 | G23: -0.206 | H23: 39.064 | I23: -13.301 | K23: =G23 -> -0.206 | L23: =IF(H23="",0,H23*0.001) -> 0.039064 | M23: =IF(I23="",0,I23*0.000001) -> -1.3301e-05 | N23: =IF(J23="",0,J23*100000) -> 0
A24: Orgánicos diversos | B24: 1,3-Butadieno | C24: 1,3-Butadiene | D24: C4H6 | E24: 1500 | F24: 10.72 | G24: 2.734 | H24: 26.786 | I24: -8.882 | K24: =G24 -> 2.734 | L24: =IF(H24="",0,H24*0.001) -> 0.026786 | M24: =IF(I24="",0,I24*0.000001) -> -8.882e-06 | N24: =IF(J24="",0,J24*100000) -> 0
A25: Orgánicos diversos | B25: Ciclohexano | C25: Cyclohexane | D25: C6H12 (ciclo) | E25: 1500 | F25: 13.121 | G25: -3.876 | H25: 63.249 | I25: -20.928 | K25: =G25 -> -3.876 | L25: =IF(H25="",0,H25*0.001) -> 0.063249 | M25: =IF(I25="",0,I25*0.000001) -> -2.0928e-05 | N25: =IF(J25="",0,J25*100000) -> 0
A26: Orgánicos diversos | B26: Etanol | C26: Ethanol | D26: C2H6O | E26: 1500 | F26: 8.948 | G26: 3.518 | H26: 20.001 | I26: -6.002 | K26: =G26 -> 3.518 | L26: =IF(H26="",0,H26*0.001) -> 0.020001 | M26: =IF(I26="",0,I26*0.000001) -> -6.002e-06 | N26: =IF(J26="",0,J26*100000) -> 0
A27: Orgánicos diversos | B27: Etilbenceno | C27: Ethylbenzene | D27: C8H10 | E27: 1500 | F27: 15.993 | G27: 1.124 | H27: 55.38 | I27: -18.476 | K27: =G27 -> 1.124 | L27: =IF(H27="",0,H27*0.001) -> 0.05538 | M27: =IF(I27="",0,I27*0.000001) -> -1.8476e-05 | N27: =IF(J27="",0,J27*100000) -> 0
A28: Orgánicos diversos | B28: Óxido de etileno | C28: Ethylene oxide | D28: C2H4O (oxido) | E28: 1000 | F28: 5.784 | G28: -0.385 | H28: 23.463 | I28: -9.296 | K28: =G28 -> -0.385 | L28: =IF(H28="",0,H28*0.001) -> 0.023463 | M28: =IF(I28="",0,I28*0.000001) -> -9.296e-06 | N28: =IF(J28="",0,J28*100000) -> 0
A29: Orgánicos diversos | B29: Formaldehído | C29: Formaldehyde | D29: CH2O | E29: 1500 | F29: 4.191 | G29: 2.264 | H29: 7.022 | I29: -1.877 | K29: =G29 -> 2.264 | L29: =IF(H29="",0,H29*0.001) -> 0.007022 | M29: =IF(I29="",0,I29*0.000001) -> -1.877e-06 | N29: =IF(J29="",0,J29*100000) -> 0
A30: Orgánicos diversos | B30: Metanol | C30: Methanol | D30: CH4O | E30: 1500 | F30: 5.547 | G30: 2.211 | H30: 12.216 | I30: -3.45 | K30: =G30 -> 2.211 | L30: =IF(H30="",0,H30*0.001) -> 0.012216 | M30: =IF(I30="",0,I30*0.000001) -> -3.45e-06 | N30: =IF(J30="",0,J30*100000) -> 0
A31: Orgánicos diversos | B31: Estireno | C31: Styrene | D31: C8H8 | E31: 1500 | F31: 15.534 | G31: 2.05 | H31: 50.192 | I31: -16.662 | K31: =G31 -> 2.05 | L31: =IF(H31="",0,H31*0.001) -> 0.050192 | M31: =IF(I31="",0,I31*0.000001) -> -1.6662e-05 | N31: =IF(J31="",0,J31*100000) -> 0
A32: Orgánicos diversos | B32: Tolueno | C32: Toluene | D32: C7H8 | E32: 1500 | F32: 12.922 | G32: 0.29 | H32: 47.052 | I32: -15.716 | K32: =G32 -> 0.29 | L32: =IF(H32="",0,H32*0.001) -> 0.047052 | M32: =IF(I32="",0,I32*0.000001) -> -1.5716e-05 | N32: =IF(J32="",0,J32*100000) -> 0
A33: Inorgánicos diversos | B33: Aire | C33: Air | D33: Aire | E33: 2000 | F33: 3.509 | G33: 3.355 | H33: 0.575 | J33: -0.016 | K33: =G33 -> 3.355 | L33: =IF(H33="",0,H33*0.001) -> 0.000575 | M33: =IF(I33="",0,I33*0.000001) -> 0 | N33: =IF(J33="",0,J33*100000) -> -1600
A34: Inorgánicos diversos | B34: Amoniaco | C34: Ammonia | D34: NH3 | E34: 1800 | F34: 4.269 | G34: 3.578 | H34: 3.02 | J34: -0.186 | K34: =G34 -> 3.578 | L34: =IF(H34="",0,H34*0.001) -> 0.00302 | M34: =IF(I34="",0,I34*0.000001) -> 0 | N34: =IF(J34="",0,J34*100000) -> -18600
A35: Inorgánicos diversos | B35: Bromo | C35: Bromine | D35: Br2 | E35: 3000 | F35: 4.337 | G35: 4.493 | H35: 0.056 | J35: -0.154 | K35: =G35 -> 4.493 | L35: =IF(H35="",0,H35*0.001) -> 5.6e-05 | M35: =IF(I35="",0,I35*0.000001) -> 0 | N35: =IF(J35="",0,J35*100000) -> -15400
A36: Inorgánicos diversos | B36: Monóxido de carbono | C36: Carbon monoxide | D36: CO | E36: 2500 | F36: 3.507 | G36: 3.376 | H36: 0.557 | J36: -0.031 | K36: =G36 -> 3.376 | L36: =IF(H36="",0,H36*0.001) -> 0.000557 | M36: =IF(I36="",0,I36*0.000001) -> 0 | N36: =IF(J36="",0,J36*100000) -> -3100
A37: Inorgánicos diversos | B37: Dióxido de carbono | C37: Carbon dioxide | D37: CO2 | E37: 2000 | F37: 4.467 | G37: 5.457 | H37: 1.045 | J37: -1.157 | K37: =G37 -> 5.457 | L37: =IF(H37="",0,H37*0.001) -> 0.001045 | M37: =IF(I37="",0,I37*0.000001) -> 0 | N37: =IF(J37="",0,J37*100000) -> -115700
A38: Inorgánicos diversos | B38: Disulfuro de carbono | C38: Carbon disulfide | D38: CS2 | E38: 1800 | F38: 5.532 | G38: 6.311 | H38: 0.805 | J38: -0.906 | K38: =G38 -> 6.311 | L38: =IF(H38="",0,H38*0.001) -> 0.000805 | M38: =IF(I38="",0,I38*0.000001) -> 0 | N38: =IF(J38="",0,J38*100000) -> -90600
A39: Inorgánicos diversos | B39: Cloro | C39: Chlorine | D39: Cl2 | E39: 3000 | F39: 4.082 | G39: 4.442 | H39: 0.089 | J39: -0.344 | K39: =G39 -> 4.442 | L39: =IF(H39="",0,H39*0.001) -> 8.9e-05 | M39: =IF(I39="",0,I39*0.000001) -> 0 | N39: =IF(J39="",0,J39*100000) -> -34400
A40: Inorgánicos diversos | B40: Hidrógeno | C40: Hydrogen | D40: H2 | E40: 3000 | F40: 3.468 | G40: 3.249 | H40: 0.422 | J40: 0.083 | K40: =G40 -> 3.249 | L40: =IF(H40="",0,H40*0.001) -> 0.000422 | M40: =IF(I40="",0,I40*0.000001) -> 0 | N40: =IF(J40="",0,J40*100000) -> 8300
A41: Inorgánicos diversos | B41: Sulfuro de hidrógeno | C41: Hydrogen sulfide | D41: H2S | E41: 2300 | F41: 4.114 | G41: 3.931 | H41: 1.49 | J41: -0.232 | K41: =G41 -> 3.931 | L41: =IF(H41="",0,H41*0.001) -> 0.00149 | M41: =IF(I41="",0,I41*0.000001) -> 0 | N41: =IF(J41="",0,J41*100000) -> -23200
A42: Inorgánicos diversos | B42: Cloruro de hidrógeno | C42: Hydrogen chloride | D42: HCl | E42: 2000 | F42: 3.512 | G42: 3.156 | H42: 0.623 | J42: 0.151 | K42: =G42 -> 3.156 | L42: =IF(H42="",0,H42*0.001) -> 0.000623 | M42: =IF(I42="",0,I42*0.000001) -> 0 | N42: =IF(J42="",0,J42*100000) -> 15100
A43: Inorgánicos diversos | B43: Cianuro de hidrógeno | C43: Hydrogen cyanide | D43: HCN | E43: 2500 | F43: 4.326 | G43: 4.736 | H43: 1.359 | J43: -0.725 | K43: =G43 -> 4.736 | L43: =IF(H43="",0,H43*0.001) -> 0.001359 | M43: =IF(I43="",0,I43*0.000001) -> 0 | N43: =IF(J43="",0,J43*100000) -> -72500
A44: Inorgánicos diversos | B44: Nitrógeno | C44: Nitrogen | D44: N2 | E44: 2000 | F44: 3.502 | G44: 3.28 | H44: 0.593 | J44: 0.04 | K44: =G44 -> 3.28 | L44: =IF(H44="",0,H44*0.001) -> 0.000593 | M44: =IF(I44="",0,I44*0.000001) -> 0 | N44: =IF(J44="",0,J44*100000) -> 4000
... A52: Inorgánicos diversos | B52: Agua | C52: Water | D52: H2O | E52: 2000 | F52: 4.038 | G52: 3.47 | H52: 1.45 | J52: 0.121 | K52: =G52 -> 3.47 | L52: =IF(H52="",0,H52*0.001) -> 0.00145 | M52: =IF(I52="",0,I52*0.000001) -> 0 | N52: =IF(J52="",0,J52*100000) -> 12100
...

Sheet C2_Solidos
A1: Tabla C.2: Capacidades caloríficas de sólidos
A2: Cp/R = A + B·T + D·T⁻² T (K) de 298 a Tmáx.
A4: Especie | B4: Species | C4: Fórmula | D4: Tmáx /K | E4: Cp298/R | F4: A | G4: 10³ B | H4: 10⁻⁵ D | I4: A (real) | J4: B (real) | K4: D (real)
A5: Óxido de calcio | B5: Calcium oxide | C5: CaO | D5: 2000 | E5: 5.058 | F5: 6.104 | G5: 0.443 | H5: -1.047 | I5: =F5 -> 6.104 | J5: =IF(G5="",0,G5*0.001) -> 0.000443 | K5: =IF(H5="",0,H5*100000) -> -104700
A6: Carbonato de calcio | B6: Calcium carbonate | C6: CaCO3 | D6: 1200 | E6: 9.848 | F6: 12.572 | G6: 2.637 | H6: -3.12 | I6: =F6 -> 12.572 | J6: =IF(G6="",0,G6*0.001) -> 0.002637 | K6: =IF(H6="",0,H6*100000) -> -312000
A7: Hidróxido de calcio | B7: Calcium hydroxide | C7: Ca(OH)2 | D7: 700 | E7: 11.217 | F7: 9.597 | G7: 5.435 | I7: =F7 -> 9.597 | J7: =IF(G7="",0,G7*0.001) -> 0.005435 | K7: =IF(H7="",0,H7*100000) -> 0
A8: Carburo de calcio | B8: Calcium carbide | C8: CaC2 | D8: 720 | E8: 7.508 | F8: 8.254 | G8: 1.429 | H8: -1.042 | I8: =F8 -> 8.254 | J8: =IF(G8="",0,G8*0.001) -> 0.001429 | K8: =IF(H8="",0,H8*100000) -> -104200
A9: Cloruro de calcio | B9: Calcium chloride | C9: CaCl2 | D9: 1055 | E9: 8.762 | F9: 8.646 | G9: 1.53 | H9: -0.302 | I9: =F9 -> 8.646 | J9: =IF(G9="",0,G9*0.001) -> 0.00153 | K9: =IF(H9="",0,H9*100000) -> -30200
A10: Carbono (grafito) | B10: Carbon (graphite) | C10: C | D10: 2000 | E10: 1.026 | F10: 1.771 | G10: 0.771 | H10: -0.867 | I10: =F10 -> 1.771 | J10: =IF(G10="",0,G10*0.001) -> 0.000771 | K10: =IF(H10="",0,H10*100000) -> -86700
A11: Cobre | B11: Copper | C11: Cu | D11: 1357 | E11: 2.959 | F11: 2.677 | G11: 0.815 | H11: 0.035 | I11: =F11 -> 2.677 | J11: =IF(G11="",0,G11*0.001) -> 0.000815 | K11: =IF(H11="",0,H11*100000) -> 3500
A12: Óxido de cobre | B12: Copper oxide | C12: CuO | D12: 1400 | E12: 5.087 | F12: 5.78 | G12: 0.973 | H12: -0.874 | I12: =F12 -> 5.78 | J12: =IF(G12="",0,G12*0.001) -> 0.000973 | K12: =IF(H12="",0,H12*100000) -> -87400
A13: Hierro (α) | B13: Iron (α) | C13: Fe | D13: 1043 | E13: 3.005 | F13: -0.111 | G13: 6.111 | H13: 1.15 | I13: =F13 -> -0.111 | J13: =IF(G13="",0,G13*0.001) -> 0.006111 | K13: =IF(H13="",0,H13*100000) -> 115000
A14: Óxido de hierro (hematita) | B14: Iron oxide (hematite) | C14: Fe2O3 | D14: 960 | E14: 12.48 | F14: 11.812 | G14: 9.697 | H14: -1.976 | I14: =F14 -> 11.812 | J14: =IF(G14="",0,G14*0.001) -> 0.009697 | K14: =IF(H14="",0,H14*100000) -> -197600
A15: Óxido de hierro (magnetita) | B15: Iron oxide (magnetite) | C15: Fe3O4 | D15: 850 | E15: 18.138 | F15: 9.594 | G15: 27.112 | H15: 0.409 | I15: =F15 -> 9.594 | J15: =IF(G15="",0,G15*0.001) -> 0.027112 | K15: =IF(H15="",0,H15*100000) -> 40900
A16: Sulfuro de hierro | B16: Iron sulfide | C16: FeS | D16: 411 | E16: 6.573 | F16: 2.612 | G16: 13.286 | I16: =F16 -> 2.612 | J16: =IF(G16="",0,G16*0.001) -> 0.013286 | K16: =IF(H16="",0,H16*100000) -> 0
A17: Yodo | B17: Iodine | C17: I2 | D17: 386.8 | E17: 6.929 | F17: 6.481 | G17: 1.502 | I17: =F17 -> 6.481 | J17: =IF(G17="",0,G17*0.001) -> 0.001502 | K17: =IF(H17="",0,H17*100000) -> 0
A18: Cloruro de litio | B18: Lithium chloride | C18: LiCl | D18: 800 | E18: 5.778 | F18: 5.257 | G18: 2.476 | H18: -0.193 | I18: =F18 -> 5.257 | J18: =IF(G18="",0,G18*0.001) -> 0.002476 | K18: =IF(H18="",0,H18*100000) -> -19300
A19: Cloruro de amonio | B19: Ammonium chloride | C19: NH4Cl | D19: 458 | E19: 10.741 | F19: 5.939 | G19: 16.105 | I19: =F19 -> 5.939 | J19: =IF(G19="",0,G19*0.001) -> 0.016105 | K19: =IF(H19="",0,H19*100000) -> 0
A20: Sodio | B20: Sodium | C20: Na | D20: 371 | E20: 3.386 | F20: 1.988 | G20: 4.688 | I20: =F20 -> 1.988 | J20: =IF(G20="",0,G20*0.001) -> 0.004688 | K20: =IF(H20="",0,H20*100000) -> 0
A21: Cloruro de sodio | B21: Sodium chloride | C21: NaCl | D21: 1073 | E21: 6.111 | F21: 5.526 | G21: 1.963 | I21: =F21 -> 5.526 | J21: =IF(G21="",0,G21*0.001) -> 0.001963 | K21: =IF(H21="",0,H21*100000) -> 0
A22: Hidróxido de sodio | B22: Sodium hydroxide | C22: NaOH | D22: 566 | E22: 7.177 | F22: 0.121 | G22: 16.316 | H22: 1.948 | I22: =F22 -> 0.121 | J22: =IF(G22="",0,G22*0.001) -> 0.016316 | K22: =IF(H22="",0,H22*100000) -> 194800
A23: Bicarbonato de sodio | B23: Sodium bicarbonate | C23: NaHCO3 | D23: 400 | E23: 10.539 | F23: 5.128 | G23: 18.148 | I23: =F23 -> 5.128 | J23: =IF(G23="",0,G23*0.001) -> 0.018148 | K23: =IF(H23="",0,H23*100000) -> 0
A24: Azufre (rómbico) | B24: Sulfur (rhombic) | C24: S | D24: 368.3 | E24: 3.748 | F24: 4.114 | G24: -1.728 | H24: -0.783 | I24: =F24 -> 4.114 | J24: =IF(G24="",0,G24*0.001) -> -0.001728 | K24: =IF(H24="",0,H24*100000) -> -78300
A25: Sílice (cuarzo) | B25: Silica (quartz) | C25: SiO2 | D25: 847 | E25: 5.345 | F25: 4.871 | G25: 5.365 | H25: -1.001 | I25: =F25 -> 4.871 | J25: =IF(G25="",0,G25*0.001) -> 0.005365 | K25: =IF(H25="",0,H25*100000) -> -100100

Sheet C3_Liquidos
A1: Tabla C.3: Capacidades caloríficas de líquidos
A2: Cp/R = A + B·T + C·T² T de 273.15 a 373.15 K.
A4: Especie | B4: Species | C4: Fórmula | D4: Cp298/R | E4: A | F4: 10³ B | G4: 10⁶ C | H4: A (real) | I4: B (real) | J4: C (real)
A5: Amoniaco | B5: Ammonia | C5: NH3 | D5: 9.718 | E5: 22.626 | F5: -100.75 | G5: 192.71 | H5: =E5 -> 22.626 | I5: =F5*0.001 -> -0.10075 | J5: =G5*0.000001 -> 0.00019271
A6: Anilina | B6: Aniline | C6: C6H7N | D6: 23.07 | E6: 15.819 | F6: 29.03 | G6: -15.8 | H6: =E6 -> 15.819 | I6: =F6*0.001 -> 0.02903 | J6: =G6*0.000001 -> -1.58e-05
A7: Benceno | B7: Benzene | C7: C6H6 | D7: 16.157 | E7: -0.747 | F7: 67.96 | G7: -37.78 | H7: =E7 -> -0.747 | I7: =F7*0.001 -> 0.06796 | J7: =G7*0.000001 -> -3.778e-05
A8: 1,3-Butadieno | B8: 1,3-Butadiene | C8: C4H6 | D8: 14.779 | E8: 22.711 | F8: -87.96 | G8: 205.79 | H8: =E8 -> 22.711 | I8: =F8*0.001 -> -0.08796 | J8: =G8*0.000001 -> 0.00020579
A9: Tetracloruro de carbono | B9: Carbon tetrachloride | C9: CCl4 | D9: 15.751 | E9: 21.155 | F9: -48.28 | G9: 101.14 | H9: =E9 -> 21.155 | I9: =F9*0.001 -> -0.04828 | J9: =G9*0.000001 -> 0.00010114
A10: Clorobenceno | B10: Chlorobenzene | C10: C6H5Cl | D10: 18.24 | E10: 11.278 | F10: 32.86 | G10: -31.9 | H10: =E10 -> 11.278 | I10: =F10*0.001 -> 0.03286 | J10: =G10*0.000001 -> -3.19e-05
A11: Cloroformo | B11: Chloroform | C11: CHCl3 | D11: 13.806 | E11: 19.215 | F11: -42.89 | G11: 83.01 | H11: =E11 -> 19.215 | I11: =F11*0.001 -> -0.04289 | J11: =G11*0.000001 -> 8.301e-05
A12: Ciclohexano | B12: Cyclohexane | C12: C6H12 | D12: 18.737 | E12: -9.048 | F12: 141.38 | G12: -161.62 | H12: =E12 -> -9.048 | I12: =F12*0.001 -> 0.14138 | J12: =G12*0.000001 -> -0.00016162
A13: Etanol | B13: Ethanol | C13: C2H6O | D13: 13.444 | E13: 33.866 | F13: -172.6 | G13: 349.17 | H13: =E13 -> 33.866 | I13: =F13*0.001 -> -0.1726 | J13: =G13*0.000001 -> 0.00034917
A14: Óxido de etileno | B14: Ethylene oxide | C14: C2H4O | D14: 10.59 | E14: 21.039 | F14: -86.41 | G14: 172.28 | H14: =E14 -> 21.039 | I14: =F14*0.001 -> -0.08641 | J14: =G14*0.000001 -> 0.00017228
A15: Metanol | B15: Methanol | C15: CH4O | D15: 9.798 | E15: 13.431 | F15: -51.28 | G15: 131.13 | H15: =E15 -> 13.431 | I15: =F15*0.001 -> -0.05128 | J15: =G15*0.000001 -> 0.00013113
A16: n-Propanol | B16: n-Propanol | C16: C3H8O | D16: 16.921 | E16: 41.653 | F16: -210.32 | G16: 427.2 | H16: =E16 -> 41.653 | I16: =F16*0.001 -> -0.21032 | J16: =G16*0.000001 -> 0.0004272
... A19: Agua | B19: Water | C19: H2O | D19: 9.069 | E19: 8.712 | F19: 1.25 | G19: -0.18 | H19: =E19 -> 8.712 | I19: =F19*0.001 -> 0.00125 | J19: =G19*0.000001 -> -1.8e-07

Sheet C4_Formacion
A1: Tabla C.4: Entalpías estándar y energías de Gibbs de formación a 298.15 K
A2: J por mol de sustancia formada. Estado estándar: (g) gas ideal puro a 1 bar; (l),(s) sustancia pura a 1 bar; (ac) solución ideal hipotética 1 molal. Clave = Fórmula + (estado).
A4: Grupo | B4: Especie | C4: Species | D4: Fórmula | E4: Estado | F4: Clave | G4: ΔH°f298 /J·mol⁻¹ | H4: ΔG°f298 /J·mol⁻¹
A5: Parafinas | B5: Metano | C5: Methane | D5: CH4 | E5: g | F5: =D5&"("&E5&")" -> CH4(g) | G5: -74520 | H5: -50460
A6: Parafinas | B6: Etano | C6: Ethane | D6: C2H6 | E6: g | F6: =D6&"("&E6&")" -> C2H6(g) | G6: -83820 | H6: -31855
A7: Parafinas | B7: Propano | C7: Propane | D7: C3H8 | E7: g | F7: =D7&"("&E7&")" -> C3H8(g) | G7: -104680 | H7: -24290
A8: Parafinas | B8: n-Butano | C8: n-Butane | D8: C4H10 | E8: g | F8: =D8&"("&E8&")" -> C4H10(g) | G8: -125790 | H8: -16570
A9: Parafinas | B9: n-Pentano | C9: n-Pentane | D9: C5H12 | E9: g | F9: =D9&"("&E9&")" -> C5H12(g) | G9: -146760 | H9: -8650
A10: Parafinas | B10: n-Hexano | C10: n-Hexane | D10: C6H14 | E10: g | F10: =D10&"("&E10&")" -> C6H14(g) | G10: -166920 | H10: 150
A11: Parafinas | B11: n-Heptano | C11: n-Heptane | D11: C7H16 | E11: g | F11: =D11&"("&E11&")" -> C7H16(g) | G11: -187780 | H11: 8260
A12: Parafinas | B12: n-Octano | C12: n-Octane | D12: C8H18 | E12: g | F12: =D12&"("&E12&")" -> C8H18(g) | G12: -208750 | H12: 16260
A13: 1-Alquenos | B13: Etileno | C13: Ethylene | D13: C2H4 | E13: g | F13: =D13&"("&E13&")" -> C2H4(g) | G13: 52510 | H13: 68460
A14: 1-Alquenos | B14: Propileno | C14: Propylene | D14: C3H6 | E14: g | F14: =D14&"("&E14&")" -> C3H6(g) | G14: 19710 | H14: 62205
A15: 1-Alquenos | B15: 1-Buteno | C15: 1-Butene | D15: C4H8 | E15: g | F15: =D15&"("&E15&")" -> C4H8(g) | G15: -540 | H15: 70340
A16: 1-Alquenos | B16: 1-Penteno | C16: 1-Pentene | D16: C5H10 | E16: g | F16: =D16&"("&E16&")" -> C5H10(g) | G16: -21280 | H16: 78410
A17: 1-Alquenos | B17: 1-Hexeno | C17: 1-Hexene | D17: C6H12 | E17: g | F17: =D17&"("&E17&")" -> C6H12(g) | G17: -41950 | H17: 86830
A18: 1-Alquenos | B18: 1-Hepteno | C18: 1-Heptene | D18: C7H14 | E18: g | F18: =D18&"("&E18&")" -> C7H14(g) | G18: -62760
A19: Orgánicos diversos | B19: Acetaldehído | C19: Acetaldehyde | D19: C2H4O | E19: g | F19: =D19&"("&E19&")" -> C2H4O(g) | G19: -166190 | H19: -128860
A20: Orgánicos diversos | B20: Ácido acético | C20: Acetic acid | D20: C2H4O2 | E20: l | F20: =D20&"("&E20&")" -> C2H4O2(l) | G20: -484500 | H20: -389900
A21: Orgánicos diversos | B21: Acetileno | C21: Acetylene | D21: C2H2 | E21: g | F21: =D21&"("&E21&")" -> C2H2(g) | G21: 227480 | H21: 209970
A22: Orgánicos diversos | B22: Benceno | C22: Benzene | D22: C6H6 | E22: g | F22: =D22&"("&E22&")" -> C6H6(g) | G22: 82930 | H22: 129665
A23: Orgánicos diversos | B23: Benceno | C23: Benzene | D23: C6H6 | E23: l | F23: =D23&"("&E23&")" -> C6H6(l) | G23: 49080 | H23: 124520
A24: Orgánicos diversos | B24: 1,3-Butadieno | C24: 1,3-Butadiene | D24: C4H6 | E24: g | F24: =D24&"("&E24&")" -> C4H6(g) | G24: 109240 | H24: 149795
A25: Orgánicos diversos | B25: Ciclohexano | C25: Cyclohexane | D25: C6H12 (ciclo) | E25: g | F25: =D25&"("&E25&")" -> C6H12 (ciclo)(g) | G25: -123140 | H25: 31920
A26: Orgánicos diversos | B26: Ciclohexano | C26: Cyclohexane | D26: C6H12 (ciclo) | E26: l | F26: =D26&"("&E26&")" -> C6H12 (ciclo)(l) | G26: -156230 | H26: 26850
A27: Orgánicos diversos | B27: 1,2-Etanodiol | C27: 1,2-Ethanediol | D27: C2H6O2 | E27: l | F27: =D27&"("&E27&")" -> C2H6O2(l) | G27: -454800 | H27: -323080
A28: Orgánicos diversos | B28: Etanol | C28: Ethanol | D28: C2H6O | E28: g | F28: =D28&"("&E28&")" -> C2H6O(g) | G28: -235100 | H28: -168490
A29: Orgánicos diversos | B29: Etanol | C29: Ethanol | D29: C2H6O | E29: l | F29: =D29&"("&E29&")" -> C2H6O(l) | G29: -277690 | H29: -174780
A30: Orgánicos diversos | B30: Etilbenceno | C30: Ethylbenzene | D30: C8H10 | E30: g | F30: =D30&"("&E30&")" -> C8H10(g) | G30: 29920 | H30: 130890
... A40: Inorgánicos diversos | B40: Amoniaco | C40: Ammonia | D40: NH3 | E40: g | F40: =D40&"("&E40&")" -> NH3(g) | G40: -46110 | H40: -16450
A41: Inorgánicos diversos | B41: Amoniaco | C41: Ammonia | D41: NH3 | E41: ac | F41: =D41&"("&E41&")" -> NH3(ac) | H41: -26500
A42: Inorgánicos diversos | B42: Carburo de calcio | C42: Calcium carbide | D42: CaC2 | E42: s | F42: =D42&"("&E42&")" -> CaC2(s) | G42: -59800 | H42: -64900
A43: Inorgánicos diversos | B43: Carbonato de calcio | C43: Calcium carbonate | D43: CaCO3 | E43: s | F43: =D43&"("&E43&")" -> CaCO3(s) | G43: -1206920 | H43: -1128790
A44: Inorgánicos diversos | B44: Cloruro de calcio | C44: Calcium chloride | D44: CaCl2 | E44: s | F44: =D44&"("&E44&")" -> CaCl2(s) | G44: -795800 | H44: -748100
A45: Inorgánicos diversos | B45: Cloruro de calcio | C45: Calcium chloride | D45: CaCl2 | E45: ac | F45: =D45&"("&E45&")" -> CaCl2(ac) | H45: -8101900
A46: Inorgánicos diversos | B46: Cloruro de calcio | C46: Calcium chloride | D46: CaCl2·6H2O | E46: s | F46: =D46&"("&E46&")" -> CaCl2·6H2O(s) | G46: -2607900
A47: Inorgánicos diversos | B47: Hidróxido de calcio | C47: Calcium hydroxide | D47: Ca(OH)2 | E47: s | F47: =D47&"("&E47&")" -> Ca(OH)2(s) | G47: -986090 | H47: -898490
A48: Inorgánicos diversos | B48: Hidróxido de calcio | C48: Calcium hydroxide | D48: Ca(OH)2 | E48: ac | F48: =D48&"("&E48&")" -> Ca(OH)2(ac) | H48: -868070
A49: Inorgánicos diversos | B49: Óxido de calcio | C49: Calcium oxide | D49: CaO | E49: s | F49: =D49&"("&E49&")" -> CaO(s) | G49: -635090 | H49: -604030
A50: Inorgánicos diversos | B50: Dióxido de carbono | C50: Carbon dioxide | D50: CO2 | E50: g | F50: =D50&"("&E50&")" -> CO2(g) | G50: -393509 | H50: -394359
...

Sheet BD_Gases
A1: BD_Gases — maestro por especie gaseosa (gas ideal)
A2: Todo por INDEX/MATCH a C1_Gases y C4_Formacion. Hf, Gf en J/mol; A, B, C, D reales (Cp/R = A + B·T + C·T² + D·T⁻²). Esta hoja es la que se copia a cada libro de ejercicio.
A4: Fórmula | B4: Especie | C4: ΔH°f298 /J·mol⁻¹ | D4: ΔG°f298 /J·mol⁻¹ | E4: A | F4: B | G4: C | H4: D | I4: Tmáx /K | J4: Cp298/R | K4: Fuente Hf/Gf
A5: CH4 | B5: Metano | C5: =INDEX(C4_Formacion!$G:$G,MATCH(A5&"(g)",C4_Formacion!$F:$F,0)) -> -74520 | D5: =INDEX(C4_Formacion!$H:$H,MATCH(A5&"(g)",C4_Formacion!$F:$F,0)) -> -50460 | E5: =INDEX(C1_Gases!$K:$K,MATCH($A5,C1_Gases!$D:$D,0)) -> 1.702 | F5: =INDEX(C1_Gases!$L:$L,MATCH($A5,C1_Gases!$D:$D,0)) -> 0.009081 | G5: =INDEX(C1_Gases!$M:$M,MATCH($A5,C1_Gases!$D:$D,0)) -> -2.164e-06 | H5: =INDEX(C1_Gases!$N:$N,MATCH($A5,C1_Gases!$D:$D,0)) -> 0 | I5: =INDEX(C1_Gases!$E:$E,MATCH($A5,C1_Gases!$D:$D,0)) -> 1500 | J5: =INDEX(C1_Gases!$F:$F,MATCH($A5,C1_Gases!$D:$D,0)) -> 4.217 | K5: Tabla C.4 (g)
A6: C2H6 | B6: Etano | C6: =INDEX(C4_Formacion!$G:$G,MATCH(A6&"(g)",C4_Formacion!$F:$F,0)) -> -83820 | D6: =INDEX(C4_Formacion!$H:$H,MATCH(A6&"(g)",C4_Formacion!$F:$F,0)) -> -31855 | E6: =INDEX(C1_Gases!$K:$K,MATCH($A6,C1_Gases!$D:$D,0)) -> 1.131 | F6: =INDEX(C1_Gases!$L:$L,MATCH($A6,C1_Gases!$D:$D,0)) -> 0.019225 | G6: =INDEX(C1_Gases!$M:$M,MATCH($A6,C1_Gases!$D:$D,0)) -> -5.561e-06 | H6: =INDEX(C1_Gases!$N:$N,MATCH($A6,C1_Gases!$D:$D,0)) -> 0 | I6: =INDEX(C1_Gases!$E:$E,MATCH($A6,C1_Gases!$D:$D,0)) -> 1500 | J6: =INDEX(C1_Gases!$F:$F,MATCH($A6,C1_Gases!$D:$D,0)) -> 6.369 | K6: Tabla C.4 (g)
A7: C3H8 | B7: Propano | C7: =INDEX(C4_Formacion!$G:$G,MATCH(A7&"(g)",C4_Formacion!$F:$F,0)) -> -104680 | D7: =INDEX(C4_Formacion!$H:$H,MATCH(A7&"(g)",C4_Formacion!$F:$F,0)) -> -24290 | E7: =INDEX(C1_Gases!$K:$K,MATCH($A7,C1_Gases!$D:$D,0)) -> 1.213 | F7: =INDEX(C1_Gases!$L:$L,MATCH($A7,C1_Gases!$D:$D,0)) -> 0.028785 | G7: =INDEX(C1_Gases!$M:$M,MATCH($A7,C1_Gases!$D:$D,0)) -> -8.824e-06 | H7: =INDEX(C1_Gases!$N:$N,MATCH($A7,C1_Gases!$D:$D,0)) -> 0 | I7: =INDEX(C1_Gases!$E:$E,MATCH($A7,C1_Gases!$D:$D,0)) -> 1500 | J7: =INDEX(C1_Gases!$F:$F,MATCH($A7,C1_Gases!$D:$D,0)) -> 9.011 | K7: Tabla C.4 (g)
A8: C4H10 | B8: n-Butano | C8: =INDEX(C4_Formacion!$G:$G,MATCH(A8&"(g)",C4_Formacion!$F:$F,0)) -> -125790 | D8: =INDEX(C4_Formacion!$H:$H,MATCH(A8&"(g)",C4_Formacion!$F:$F,0)) -> -16570 | E8: =INDEX(C1_Gases!$K:$K,MATCH($A8,C1_Gases!$D:$D,0)) -> 1.935 | F8: =INDEX(C1_Gases!$L:$L,MATCH($A8,C1_Gases!$D:$D,0)) -> 0.036915 | G8: =INDEX(C1_Gases!$M:$M,MATCH($A8,C1_Gases!$D:$D,0)) -> -1.1402e-05 | H8: =INDEX(C1_Gases!$N:$N,MATCH($A8,C1_Gases!$D:$D,0)) -> 0 | I8: =INDEX(C1_Gases!$E:$E,MATCH($A8,C1_Gases!$D:$D,0)) -> 1500 | J8: =INDEX(C1_Gases!$F:$F,MATCH($A8,C1_Gases!$D:$D,0)) -> 11.928 | K8: Tabla C.4 (g)
A9: C4H10 (iso) | B9: iso-Butano | E9: =INDEX(C1_Gases!$K:$K,MATCH($A9,C1_Gases!$D:$D,0)) -> 1.677 | F9: =INDEX(C1_Gases!$L:$L,MATCH($A9,C1_Gases!$D:$D,0)) -> 0.037853 | G9: =INDEX(C1_Gases!$M:$M,MATCH($A9,C1_Gases!$D:$D,0)) -> -1.1945e-05 | H9: =INDEX(C1_Gases!$N:$N,MATCH($A9,C1_Gases!$D:$D,0)) -> 0 | I9: =INDEX(C1_Gases!$E:$E,MATCH($A9,C1_Gases!$D:$D,0)) -> 1500 | J9: =INDEX(C1_Gases!$F:$F,MATCH($A9,C1_Gases!$D:$D,0)) -> 11.901 | K9: No está en C.4 (solo Cp)
A10: C5H12 | B10: n-Pentano | C10: =INDEX(C4_Formacion!$G:$G,MATCH(A10&"(g)",C4_Formacion!$F:$F,0)) -> -146760 | D10: =INDEX(C4_Formacion!$H:$H,MATCH(A10&"(g)",C4_Formacion!$F:$F,0)) -> -8650 | E10: =INDEX(C1_Gases!$K:$K,MATCH($A10,C1_Gases!$D:$D,0)) -> 2.464 | F10: =INDEX(C1_Gases!$L:$L,MATCH($A10,C1_Gases!$D:$D,0)) -> 0.045351 | G10: =INDEX(C1_Gases!$M:$M,MATCH($A10,C1_Gases!$D:$D,0)) -> -1.4111e-05 | H10: =INDEX(C1_Gases!$N:$N,MATCH($A10,C1_Gases!$D:$D,0)) -> 0 | I10: =INDEX(C1_Gases!$E:$E,MATCH($A10,C1_Gases!$D:$D,0)) -> 1500 | J10: =INDEX(C1_Gases!$F:$F,MATCH($A10,C1_Gases!$D:$D,0)) -> 14.731 | K10: Tabla C.4 (g)
A11: C6H14 | B11: n-Hexano | C11: =INDEX(C4_Formacion!$G:$G,MATCH(A11&"(g)",C4_Formacion!$F:$F,0)) -> -166920 | D11: =INDEX(C4_Formacion!$H:$H,MATCH(A11&"(g)",C4_Formacion!$F:$F,0)) -> 150 | E11: =INDEX(C1_Gases!$K:$K,MATCH($A11,C1_Gases!$D:$D,0)) -> 3.025 | F11: =INDEX(C1_Gases!$L:$L,MATCH($A11,C1_Gases!$D:$D,0)) -> 0.053722 | G11: =INDEX(C1_Gases!$M:$M,MATCH($A11,C1_Gases!$D:$D,0)) -> -1.6791e-05 | H11: =INDEX(C1_Gases!$N:$N,MATCH($A11,C1_Gases!$D:$D,0)) -> 0 | I11: =INDEX(C1_Gases!$E:$E,MATCH($A11,C1_Gases!$D:$D,0)) -> 1500 | J11: =INDEX(C1_Gases!$F:$F,MATCH($A11,C1_Gases!$D:$D,0)) -> 17.55 | K11: Tabla C.4 (g)
A12: C7H16 | B12: n-Heptano | C12: =INDEX(C4_Formacion!$G:$G,MATCH(A12&"(g)",C4_Formacion!$F:$F,0)) -> -187780 | D12: =INDEX(C4_Formacion!$H:$H,MATCH(A12&"(g)",C4_Formacion!$F:$F,0)) -> 8260 | E12: =INDEX(C1_Gases!$K:$K,MATCH($A12,C1_Gases!$D:$D,0)) -> 3.57 | F12: =INDEX(C1_Gases!$L:$L,MATCH($A12,C1_Gases!$D:$D,0)) -> 0.062127 | G12: =INDEX(C1_Gases!$M:$M,MATCH($A12,C1_Gases!$D:$D,0)) -> -1.9486e-05 | H12: =INDEX(C1_Gases!$N:$N,MATCH($A12,C1_Gases!$D:$D,0)) -> 0 | I12: =INDEX(C1_Gases!$E:$E,MATCH($A12,C1_Gases!$D:$D,0)) -> 1500 | J12: =INDEX(C1_Gases!$F:$F,MATCH($A12,C1_Gases!$D:$D,0)) -> 20.361 | K12: Tabla C.4 (g)
A13: C8H18 | B13: n-Octano | C13: =INDEX(C4_Formacion!$G:$G,MATCH(A13&"(g)",C4_Formacion!$F:$F,0)) -> -208750 | D13: =INDEX(C4_Formacion!$H:$H,MATCH(A13&"(g)",C4_Formacion!$F:$F,0)) -> 16260 | E13: =INDEX(C1_Gases!$K:$K,MATCH($A13,C1_Gases!$D:$D,0)) -> 4.108 | F13: =INDEX(C1_Gases!$L:$L,MATCH($A13,C1_Gases!$D:$D,0)) -> 0.070567 | G13: =INDEX(C1_Gases!$M:$M,MATCH($A13,C1_Gases!$D:$D,0)) -> -2.2208e-05 | H13: =INDEX(C1_Gases!$N:$N,MATCH($A13,C1_Gases!$D:$D,0)) -> 0 | I13: =INDEX(C1_Gases!$E:$E,MATCH($A13,C1_Gases!$D:$D,0)) -> 1500 | J13: =INDEX(C1_Gases!$F:$F,MATCH($A13,C1_Gases!$D:$D,0)) -> 23.174 | K13: Tabla C.4 (g)
A14: C2H4 | B14: Etileno | C14: =INDEX(C4_Formacion!$G:$G,MATCH(A14&"(g)",C4_Formacion!$F:$F,0)) -> 52510 | D14: =INDEX(C4_Formacion!$H:$H,MATCH(A14&"(g)",C4_Formacion!$F:$F,0)) -> 68460 | E14: =INDEX(C1_Gases!$K:$K,MATCH($A14,C1_Gases!$D:$D,0)) -> 1.424 | F14: =INDEX(C1_Gases!$L:$L,MATCH($A14,C1_Gases!$D:$D,0)) -> 0.014394 | G14: =INDEX(C1_Gases!$M:$M,MATCH($A14,C1_Gases!$D:$D,0)) -> -4.392e-06 | H14: =INDEX(C1_Gases!$N:$N,MATCH($A14,C1_Gases!$D:$D,0)) -> 0 | I14: =INDEX(C1_Gases!$E:$E,MATCH($A14,C1_Gases!$D:$D,0)) -> 1500 | J14: =INDEX(C1_Gases!$F:$F,MATCH($A14,C1_Gases!$D:$D,0)) -> 5.325 | K14: Tabla C.4 (g)
A15: C3H6 | B15: Propileno | C15: =INDEX(C4_Formacion!$G:$G,MATCH(A15&"(g)",C4_Formacion!$F:$F,0)) -> 19710 | D15: =INDEX(C4_Formacion!$H:$H,MATCH(A15&"(g)",C4_Formacion!$F:$F,0)) -> 62205 | E15: =INDEX(C1_Gases!$K:$K,MATCH($A15,C1_Gases!$D:$D,0)) -> 1.637 | F15: =INDEX(C1_Gases!$L:$L,MATCH($A15,C1_Gases!$D:$D,0)) -> 0.022706 | G15: =INDEX(C1_Gases!$M:$M,MATCH($A15,C1_Gases!$D:$D,0)) -> -6.915e-06 | H15: =INDEX(C1_Gases!$N:$N,MATCH($A15,C1_Gases!$D:$D,0)) -> 0 | I15: =INDEX(C1_Gases!$E:$E,MATCH($A15,C1_Gases!$D:$D,0)) -> 1500 | J15: =INDEX(C1_Gases!$F:$F,MATCH($A15,C1_Gases!$D:$D,0)) -> 7.792 | K15: Tabla C.4 (g)
A16: C4H8 | B16: 1-Buteno | C16: =INDEX(C4_Formacion!$G:$G,MATCH(A16&"(g)",C4_Formacion!$F:$F,0)) -> -540 | D16: =INDEX(C4_Formacion!$H:$H,MATCH(A16&"(g)",C4_Formacion!$F:$F,0)) -> 70340 | E16: =INDEX(C1_Gases!$K:$K,MATCH($A16,C1_Gases!$D:$D,0)) -> 1.967 | F16: =INDEX(C1_Gases!$L:$L,MATCH($A16,C1_Gases!$D:$D,0)) -> 0.03163 | G16: =INDEX(C1_Gases!$M:$M,MATCH($A16,C1_Gases!$D:$D,0)) -> -9.873e-06 | H16: =INDEX(C1_Gases!$N:$N,MATCH($A16,C1_Gases!$D:$D,0)) -> 0 | I16: =INDEX(C1_Gases!$E:$E,MATCH($A16,C1_Gases!$D:$D,0)) -> 1500 | J16: =INDEX(C1_Gases!$F:$F,MATCH($A16,C1_Gases!$D:$D,0)) -> 10.52 | K16: Tabla C.4 (g)
A17: C5H10 | B17: 1-Penteno | C17: =INDEX(C4_Formacion!$G:$G,MATCH(A17&"(g)",C4_Formacion!$F:$F,0)) -> -21280 | D17: =INDEX(C4_Formacion!$H:$H,MATCH(A17&"(g)",C4_Formacion!$F:$F,0)) -> 78410 | E17: =INDEX(C1_Gases!$K:$K,MATCH($A17,C1_Gases!$D:$D,0)) -> 2.691 | F17: =INDEX(C1_Gases!$L:$L,MATCH($A17,C1_Gases!$D:$D,0)) -> 0.039753 | G17: =INDEX(C1_Gases!$M:$M,MATCH($A17,C1_Gases!$D:$D,0)) -> -1.2447e-05 | H17: =INDEX(C1_Gases!$N:$N,MATCH($A17,C1_Gases!$D:$D,0)) -> 0 | I17: =INDEX(C1_Gases!$E:$E,MATCH($A17,C1_Gases!$D:$D,0)) -> 1500 | J17: =INDEX(C1_Gases!$F:$F,MATCH($A17,C1_Gases!$D:$D,0)) -> 13.437 | K17: Tabla C.4 (g)
A18: C6H12 | B18: 1-Hexeno | C18: =INDEX(C4_Formacion!$G:$G,MATCH(A18&"(g)",C4_Formacion!$F:$F,0)) -> -41950 | D18: =INDEX(C4_Formacion!$H:$H,MATCH(A18&"(g)",C4_Formacion!$F:$F,0)) -> 86830 | E18: =INDEX(C1_Gases!$K:$K,MATCH($A18,C1_Gases!$D:$D,0)) -> 3.22 | F18: =INDEX(C1_Gases!$L:$L,MATCH($A18,C1_Gases!$D:$D,0)) -> 0.048189 | G18: =INDEX(C1_Gases!$M:$M,MATCH($A18,C1_Gases!$D:$D,0)) -> -1.5157e-05 | H18: =INDEX(C1_Gases!$N:$N,MATCH($A18,C1_Gases!$D:$D,0)) -> 0 | I18: =INDEX(C1_Gases!$E:$E,MATCH($A18,C1_Gases!$D:$D,0)) -> 1500 | J18: =INDEX(C1_Gases!$F:$F,MATCH($A18,C1_Gases!$D:$D,0)) -> 16.24 | K18: Tabla C.4 (g)
A19: C7H14 | B19: 1-Hepteno | C19: =INDEX(C4_Formacion!$G:$G,MATCH(A19&"(g)",C4_Formacion!$F:$F,0)) -> -62760 | D19: =INDEX(C4_Formacion!$H:$H,MATCH(A19&"(g)",C4_Formacion!$F:$F,0)) -> 0 | E19: =INDEX(C1_Gases!$K:$K,MATCH($A19,C1_Gases!$D:$D,0)) -> 3.768 | F19: =INDEX(C1_Gases!$L:$L,MATCH($A19,C1_Gases!$D:$D,0)) -> 0.056588 | G19: =INDEX(C1_Gases!$M:$M,MATCH($A19,C1_Gases!$D:$D,0)) -> -1.7847e-05 | H19: =INDEX(C1_Gases!$N:$N,MATCH($A19,C1_Gases!$D:$D,0)) -> 0 | I19: =INDEX(C1_Gases!$E:$E,MATCH($A19,C1_Gases!$D:$D,0)) -> 1500 | J19: =INDEX(C1_Gases!$F:$F,MATCH($A19,C1_Gases!$D:$D,0)) -> 19.053 | K19: Tabla C.4 (g)
A20: C8H16 | B20: 1-Octeno | E20: =INDEX(C1_Gases!$K:$K,MATCH($A20,C1_Gases!$D:$D,0)) -> 4.324 | F20: =INDEX(C1_Gases!$L:$L,MATCH($A20,C1_Gases!$D:$D,0)) -> 0.06496 | G20: =INDEX(C1_Gases!$M:$M,MATCH($A20,C1_Gases!$D:$D,0)) -> -2.0521e-05 | H20: =INDEX(C1_Gases!$N:$N,MATCH($A20,C1_Gases!$D:$D,0)) -> 0 | I20: =INDEX(C1_Gases!$E:$E,MATCH($A20,C1_Gases!$D:$D,0)) -> 1500 | J20: =INDEX(C1_Gases!$F:$F,MATCH($A20,C1_Gases!$D:$D,0)) -> 21.868 | K20: No está en C.4 (solo Cp)
A21: C2H4O | B21: Acetaldehído | C21: =INDEX(C4_Formacion!$G:$G,MATCH(A21&"(g)",C4_Formacion!$F:$F,0)) -> -166190 | D21: =INDEX(C4_Formacion!$H:$H,MATCH(A21&"(g)",C4_Formacion!$F:$F,0)) -> -128860 | E21: =INDEX(C1_Gases!$K:$K,MATCH($A21,C1_Gases!$D:$D,0)) -> 1.693 | F21: =INDEX(C1_Gases!$L:$L,MATCH($A21,C1_Gases!$D:$D,0)) -> 0.017978 | G21: =INDEX(C1_Gases!$M:$M,MATCH($A21,C1_Gases!$D:$D,0)) -> -6.158e-06 | H21: =INDEX(C1_Gases!$N:$N,MATCH($A21,C1_Gases!$D:$D,0)) -> 0 | I21: =INDEX(C1_Gases!$E:$E,MATCH($A21,C1_Gases!$D:$D,0)) -> 1000 | J21: =INDEX(C1_Gases!$F:$F,MATCH($A21,C1_Gases!$D:$D,0)) -> 6.506 | K21: Tabla C.4 (g)
A22: C2H2 | B22: Acetileno | C22: =INDEX(C4_Formacion!$G:$G,MATCH(A22&"(g)",C4_Formacion!$F:$F,0)) -> 227480 | D22: =INDEX(C4_Formacion!$H:$H,MATCH(A22&"(g)",C4_Formacion!$F:$F,0)) -> 209970 | E22: =INDEX(C1_Gases!$K:$K,MATCH($A22,C1_Gases!$D:$D,0)) -> 6.132 | F22: =INDEX(C1_Gases!$L:$L,MATCH($A22,C1_Gases!$D:$D,0)) -> 0.001952 | G22: =INDEX(C1_Gases!$M:$M,MATCH($A22,C1_Gases!$D:$D,0)) -> 0 | H22: =INDEX(C1_Gases!$N:$N,MATCH($A22,C1_Gases!$D:$D,0)) -> -129900 | I22: =INDEX(C1_Gases!$E:$E,MATCH($A22,C1_Gases!$D:$D,0)) -> 1500 | J22: =INDEX(C1_Gases!$F:$F,MATCH($A22,C1_Gases!$D:$D,0)) -> 5.253 | K22: Tabla C.4 (g)
A23: C6H6 | B23: Benceno | C23: =INDEX(C4_Formacion!$G:$G,MATCH(A23&"(g)",C4_Formacion!$F:$F,0)) -> 82930 | D23: =INDEX(C4_Formacion!$H:$H,MATCH(A23&"(g)",C4_Formacion!$F:$F,0)) -> 129665 | E23: =INDEX(C1_Gases!$K:$K,MATCH($A23,C1_Gases!$D:$D,0)) -> -0.206 | F23: =INDEX(C1_Gases!$L:$L,MATCH($A23,C1_Gases!$D:$D,0)) -> 0.039064 | G23: =INDEX(C1_Gases!$M:$M,MATCH($A23,C1_Gases!$D:$D,0)) -> -1.3301e-05 | H23: =INDEX(C1_Gases!$N:$N,MATCH($A23,C1_Gases!$D:$D,0)) -> 0 | I23: =INDEX(C1_Gases!$E:$E,MATCH($A23,C1_Gases!$D:$D,0)) -> 1500 | J23: =INDEX(C1_Gases!$F:$F,MATCH($A23,C1_Gases!$D:$D,0)) -> 10.259 | K23: Tabla C.4 (g)
A24: C4H6 | B24: 1,3-Butadieno | C24: =INDEX(C4_Formacion!$G:$G,MATCH(A24&"(g)",C4_Formacion!$F:$F,0)) -> 109240 | D24: =INDEX(C4_Formacion!$H:$H,MATCH(A24&"(g)",C4_Formacion!$F:$F,0)) -> 149795 | E24: =INDEX(C1_Gases!$K:$K,MATCH($A24,C1_Gases!$D:$D,0)) -> 2.734 | F24: =INDEX(C1_Gases!$L:$L,MATCH($A24,C1_Gases!$D:$D,0)) -> 0.026786 | G24: =INDEX(C1_Gases!$M:$M,MATCH($A24,C1_Gases!$D:$D,0)) -> -8.882e-06 | H24: =INDEX(C1_Gases!$N:$N,MATCH($A24,C1_Gases!$D:$D,0)) -> 0 | I24: =INDEX(C1_Gases!$E:$E,MATCH($A24,C1_Gases!$D:$D,0)) -> 1500 | J24: =INDEX(C1_Gases!$F:$F,MATCH($A24,C1_Gases!$D:$D,0)) -> 10.72 | K24: Tabla C.4 (g)
A25: C6H12 (ciclo) | B25: Ciclohexano | C25: =INDEX(C4_Formacion!$G:$G,MATCH(A25&"(g)",C4_Formacion!$F:$F,0)) -> -123140 | D25: =INDEX(C4_Formacion!$H:$H,MATCH(A25&"(g)",C4_Formacion!$F:$F,0)) -> 31920 | E25: =INDEX(C1_Gases!$K:$K,MATCH($A25,C1_Gases!$D:$D,0)) -> -3.876 | F25: =INDEX(C1_Gases!$L:$L,MATCH($A25,C1_Gases!$D:$D,0)) -> 0.063249 | G25: =INDEX(C1_Gases!$M:$M,MATCH($A25,C1_Gases!$D:$D,0)) -> -2.0928e-05 | H25: =INDEX(C1_Gases!$N:$N,MATCH($A25,C1_Gases!$D:$D,0)) -> 0 | I25: =INDEX(C1_Gases!$E:$E,MATCH($A25,C1_Gases!$D:$D,0)) -> 1500 | J25: =INDEX(C1_Gases!$F:$F,MATCH($A25,C1_Gases!$D:$D,0)) -> 13.121 | K25: Tabla C.4 (g)
A26: C2H6O | B26: Etanol | C26: =INDEX(C4_Formacion!$G:$G,MATCH(A26&"(g)",C4_Formacion!$F:$F,0)) -> -235100 | D26: =INDEX(C4_Formacion!$H:$H,MATCH(A26&"(g)",C4_Formacion!$F:$F,0)) -> -168490 | E26: =INDEX(C1_Gases!$K:$K,MATCH($A26,C1_Gases!$D:$D,0)) -> 3.518 | F26: =INDEX(C1_Gases!$L:$L,MATCH($A26,C1_Gases!$D:$D,0)) -> 0.020001 | G26: =INDEX(C1_Gases!$M:$M,MATCH($A26,C1_Gases!$D:$D,0)) -> -6.002e-06 | H26: =INDEX(C1_Gases!$N:$N,MATCH($A26,C1_Gases!$D:$D,0)) -> 0 | I26: =INDEX(C1_Gases!$E:$E,MATCH($A26,C1_Gases!$D:$D,0)) -> 1500 | J26: =INDEX(C1_Gases!$F:$F,MATCH($A26,C1_Gases!$D:$D,0)) -> 8.948 | K26: Tabla C.4 (g)
A27: C8H10 | B27: Etilbenceno | C27: =INDEX(C4_Formacion!$G:$G,MATCH(A27&"(g)",C4_Formacion!$F:$F,0)) -> 29920 | D27: =INDEX(C4_Formacion!$H:$H,MATCH(A27&"(g)",C4_Formacion!$F:$F,0)) -> 130890 | E27: =INDEX(C1_Gases!$K:$K,MATCH($A27,C1_Gases!$D:$D,0)) -> 1.124 | F27: =INDEX(C1_Gases!$L:$L,MATCH($A27,C1_Gases!$D:$D,0)) -> 0.05538 | G27: =INDEX(C1_Gases!$M:$M,MATCH($A27,C1_Gases!$D:$D,0)) -> -1.8476e-05 | H27: =INDEX(C1_Gases!$N:$N,MATCH($A27,C1_Gases!$D:$D,0)) -> 0 | I27: =INDEX(C1_Gases!$E:$E,MATCH($A27,C1_Gases!$D:$D,0)) -> 1500 | J27: =INDEX(C1_Gases!$F:$F,MATCH($A27,C1_Gases!$D:$D,0)) -> 15.993 | K27: Tabla C.4 (g)
A28: C2H4O (oxido) | B28: Óxido de etileno | C28: =INDEX(C4_Formacion!$G:$G,MATCH(A28&"(g)",C4_Formacion!$F:$F,0)) -> -52630 | D28: =INDEX(C4_Formacion!$H:$H,MATCH(A28&"(g)",C4_Formacion!$F:$F,0)) -> -13010 | E28: =INDEX(C1_Gases!$K:$K,MATCH($A28,C1_Gases!$D:$D,0)) -> -0.385 | F28: =INDEX(C1_Gases!$L:$L,MATCH($A28,C1_Gases!$D:$D,0)) -> 0.023463 | G28: =INDEX(C1_Gases!$M:$M,MATCH($A28,C1_Gases!$D:$D,0)) -> -9.296e-06 | H28: =INDEX(C1_Gases!$N:$N,MATCH($A28,C1_Gases!$D:$D,0)) -> 0 | I28: =INDEX(C1_Gases!$E:$E,MATCH($A28,C1_Gases!$D:$D,0)) -> 1000 | J28: =INDEX(C1_Gases!$F:$F,MATCH($A28,C1_Gases!$D:$D,0)) -> 5.784 | K28: Tabla C.4 (g)
A29: CH2O | B29: Formaldehído | C29: =INDEX(C4_Formacion!$G:$G,MATCH(A29&"(g)",C4_Formacion!$F:$F,0)) -> -108570 | D29: =INDEX(C4_Formacion!$H:$H,MATCH(A29&"(g)",C4_Formacion!$F:$F,0)) -> -102530 | E29: =INDEX(C1_Gases!$K:$K,MATCH($A29,C1_Gases!$D:$D,0)) -> 2.264 | F29: =INDEX(C1_Gases!$L:$L,MATCH($A29,C1_Gases!$D:$D,0)) -> 0.007022 | G29: =INDEX(C1_Gases!$M:$M,MATCH($A29,C1_Gases!$D:$D,0)) -> -1.877e-06 | H29: =INDEX(C1_Gases!$N:$N,MATCH($A29,C1_Gases!$D:$D,0)) -> 0 | I29: =INDEX(C1_Gases!$E:$E,MATCH($A29,C1_Gases!$D:$D,0)) -> 1500 | J29: =INDEX(C1_Gases!$F:$F,MATCH($A29,C1_Gases!$D:$D,0)) -> 4.191 | K29: Tabla C.4 (g)
A30: CH4O | B30: Metanol | C30: =INDEX(C4_Formacion!$G:$G,MATCH(A30&"(g)",C4_Formacion!$F:$F,0)) -> -200660 | D30: =INDEX(C4_Formacion!$H:$H,MATCH(A30&"(g)",C4_Formacion!$F:$F,0)) -> -161960 | E30: =INDEX(C1_Gases!$K:$K,MATCH($A30,C1_Gases!$D:$D,0)) -> 2.211 | F30: =INDEX(C1_Gases!$L:$L,MATCH($A30,C1_Gases!$D:$D,0)) -> 0.012216 | G30: =INDEX(C1_Gases!$M:$M,MATCH($A30,C1_Gases!$D:$D,0)) -> -3.45e-06 | H30: =INDEX(C1_Gases!$N:$N,MATCH($A30,C1_Gases!$D:$D,0)) -> 0 | I30: =INDEX(C1_Gases!$E:$E,MATCH($A30,C1_Gases!$D:$D,0)) -> 1500 | J30: =INDEX(C1_Gases!$F:$F,MATCH($A30,C1_Gases!$D:$D,0)) -> 5.547 | K30: Tabla C.4 (g)
A31: C8H8 | B31: Estireno | C31: =INDEX(C4_Formacion!$G:$G,MATCH(A31&"(g)",C4_Formacion!$F:$F,0)) -> 147360 | D31: =INDEX(C4_Formacion!$H:$H,MATCH(A31&"(g)",C4_Formacion!$F:$F,0)) -> 213900 | E31: =INDEX(C1_Gases!$K:$K,MATCH($A31,C1_Gases!$D:$D,0)) -> 2.05 | F31: =INDEX(C1_Gases!$L:$L,MATCH($A31,C1_Gases!$D:$D,0)) -> 0.050192 | G31: =INDEX(C1_Gases!$M:$M,MATCH($A31,C1_Gases!$D:$D,0)) -> -1.6662e-05 | H31: =INDEX(C1_Gases!$N:$N,MATCH($A31,C1_Gases!$D:$D,0)) -> 0 | I31: =INDEX(C1_Gases!$E:$E,MATCH($A31,C1_Gases!$D:$D,0)) -> 1500 | J31: =INDEX(C1_Gases!$F:$F,MATCH($A31,C1_Gases!$D:$D,0)) -> 15.534 | K31: Tabla C.4 (g)
A32: C7H8 | B32: Tolueno | C32: =INDEX(C4_Formacion!$G:$G,MATCH(A32&"(g)",C4_Formacion!$F:$F,0)) -> 50170 | D32: =INDEX(C4_Formacion!$H:$H,MATCH(A32&"(g)",C4_Formacion!$F:$F,0)) -> 122050 | E32: =INDEX(C1_Gases!$K:$K,MATCH($A32,C1_Gases!$D:$D,0)) -> 0.29 | F32: =INDEX(C1_Gases!$L:$L,MATCH($A32,C1_Gases!$D:$D,0)) -> 0.047052 | G32: =INDEX(C1_Gases!$M:$M,MATCH($A32,C1_Gases!$D:$D,0)) -> -1.5716e-05 | H32: =INDEX(C1_Gases!$N:$N,MATCH($A32,C1_Gases!$D:$D,0)) -> 0 | I32: =INDEX(C1_Gases!$E:$E,MATCH($A32,C1_Gases!$D:$D,0)) -> 1500 | J32: =INDEX(C1_Gases!$F:$F,MATCH($A32,C1_Gases!$D:$D,0)) -> 12.922 | K32: Tabla C.4 (g)
A33: NH3 | B33: Amoniaco | C33: =INDEX(C4_Formacion!$G:$G,MATCH(A33&"(g)",C4_Formacion!$F:$F,0)) -> -46110 | D33: =INDEX(C4_Formacion!$H:$H,MATCH(A33&"(g)",C4_Formacion!$F:$F,0)) -> -16450 | E33: =INDEX(C1_Gases!$K:$K,MATCH($A33,C1_Gases!$D:$D,0)) -> 3.578 | F33: =INDEX(C1_Gases!$L:$L,MATCH($A33,C1_Gases!$D:$D,0)) -> 0.00302 | G33: =INDEX(C1_Gases!$M:$M,MATCH($A33,C1_Gases!$D:$D,0)) -> 0 | H33: =INDEX(C1_Gases!$N:$N,MATCH($A33,C1_Gases!$D:$D,0)) -> -18600 | I33: =INDEX(C1_Gases!$E:$E,MATCH($A33,C1_Gases!$D:$D,0)) -> 1800 | J33: =INDEX(C1_Gases!$F:$F,MATCH($A33,C1_Gases!$D:$D,0)) -> 4.269 | K33: Tabla C.4 (g)
A34: Br2 | B34: Bromo | E34: =INDEX(C1_Gases!$K:$K,MATCH($A34,C1_Gases!$D:$D,0)) -> 4.493 | F34: =INDEX(C1_Gases!$L:$L,MATCH($A34,C1_Gases!$D:$D,0)) -> 5.6e-05 | G34: =INDEX(C1_Gases!$M:$M,MATCH($A34,C1_Gases!$D:$D,0)) -> 0 | H34: =INDEX(C1_Gases!$N:$N,MATCH($A34,C1_Gases!$D:$D,0)) -> -15400 | I34: =INDEX(C1_Gases!$E:$E,MATCH($A34,C1_Gases!$D:$D,0)) -> 3000 | J34: =INDEX(C1_Gases!$F:$F,MATCH($A34,C1_Gases!$D:$D,0)) -> 4.337 | K34: No está en C.4 (solo Cp)
A35: CO | B35: Monóxido de carbono | C35: =INDEX(C4_Formacion!$G:$G,MATCH(A35&"(g)",C4_Formacion!$F:$F,0)) -> -110525 | D35: =INDEX(C4_Formacion!$H:$H,MATCH(A35&"(g)",C4_Formacion!$F:$F,0)) -> -137169 | E35: =INDEX(C1_Gases!$K:$K,MATCH($A35,C1_Gases!$D:$D,0)) -> 3.376 | F35: =INDEX(C1_Gases!$L:$L,MATCH($A35,C1_Gases!$D:$D,0)) -> 0.000557 | G35: =INDEX(C1_Gases!$M:$M,MATCH($A35,C1_Gases!$D:$D,0)) -> 0 | H35: =INDEX(C1_Gases!$N:$N,MATCH($A35,C1_Gases!$D:$D,0)) -> -3100 | I35: =INDEX(C1_Gases!$E:$E,MATCH($A35,C1_Gases!$D:$D,0)) -> 2500 | J35: =INDEX(C1_Gases!$F:$F,MATCH($A35,C1_Gases!$D:$D,0)) -> 3.507 | K35: Tabla C.4 (g)
A36: CO2 | B36: Dióxido de carbono | C36: =INDEX(C4_Formacion!$G:$G,MATCH(A36&"(g)",C4_Formacion!$F:$F,0)) -> -393509 | D36: =INDEX(C4_Formacion!$H:$H,MATCH(A36&"(g)",C4_Formacion!$F:$F,0)) -> -394359 | E36: =INDEX(C1_Gases!$K:$K,MATCH($A36,C1_Gases!$D:$D,0)) -> 5.457 | F36: =INDEX(C1_Gases!$L:$L,MATCH($A36,C1_Gases!$D:$D,0)) -> 0.001045 | G36: =INDEX(C1_Gases!$M:$M,MATCH($A36,C1_Gases!$D:$D,0)) -> 0 | H36: =INDEX(C1_Gases!$N:$N,MATCH($A36,C1_Gases!$D:$D,0)) -> -115700 | I36: =INDEX(C1_Gases!$E:$E,MATCH($A36,C1_Gases!$D:$D,0)) -> 2000 | J36: =INDEX(C1_Gases!$F:$F,MATCH($A36,C1_Gases!$D:$D,0)) -> 4.467 | K36: Tabla C.4 (g)
A37: CS2 | B37: Disulfuro de carbono | E37: =INDEX(C1_Gases!$K:$K,MATCH($A37,C1_Gases!$D:$D,0)) -> 6.311 | F37: =INDEX(C1_Gases!$L:$L,MATCH($A37,C1_Gases!$D:$D,0)) -> 0.000805 | G37: =INDEX(C1_Gases!$M:$M,MATCH($A37,C1_Gases!$D:$D,0)) -> 0 | H37: =INDEX(C1_Gases!$N:$N,MATCH($A37,C1_Gases!$D:$D,0)) -> -90600 | I37: =INDEX(C1_Gases!$E:$E,MATCH($A37,C1_Gases!$D:$D,0)) -> 1800 | J37: =INDEX(C1_Gases!$F:$F,MATCH($A37,C1_Gases!$D:$D,0)) -> 5.532 | K37: No está en C.4 (solo Cp)
A38: Cl2 | B38: Cloro | C38: 0 | D38: 0 | E38: =INDEX(C1_Gases!$K:$K,MATCH($A38,C1_Gases!$D:$D,0)) -> 4.442 | F38: =INDEX(C1_Gases!$L:$L,MATCH($A38,C1_Gases!$D:$D,0)) -> 8.9e-05 | G38: =INDEX(C1_Gases!$M:$M,MATCH($A38,C1_Gases!$D:$D,0)) -> 0 | H38: =INDEX(C1_Gases!$N:$N,MATCH($A38,C1_Gases!$D:$D,0)) -> -34400 | I38: =INDEX(C1_Gases!$E:$E,MATCH($A38,C1_Gases!$D:$D,0)) -> 3000 | J38: =INDEX(C1_Gases!$F:$F,MATCH($A38,C1_Gases!$D:$D,0)) -> 4.082 | K38: Elemento, estado estándar = 0
A39: H2 | B39: Hidrógeno | C39: 0 | D39: 0 | E39: =INDEX(C1_Gases!$K:$K,MATCH($A39,C1_Gases!$D:$D,0)) -> 3.249 | F39: =INDEX(C1_Gases!$L:$L,MATCH($A39,C1_Gases!$D:$D,0)) -> 0.000422 | G39: =INDEX(C1_Gases!$M:$M,MATCH($A39,C1_Gases!$D:$D,0)) -> 0 | H39: =INDEX(C1_Gases!$N:$N,MATCH($A39,C1_Gases!$D:$D,0)) -> 8300 | I39: =INDEX(C1_Gases!$E:$E,MATCH($A39,C1_Gases!$D:$D,0)) -> 3000 | J39: =INDEX(C1_Gases!$F:$F,MATCH($A39,C1_Gases!$D:$D,0)) -> 3.468 | K39: Elemento, estado estándar = 0
A40: H2S | B40: Sulfuro de hidrógeno | C40: =INDEX(C4_Formacion!$G:$G,MATCH(A40&"(g)",C4_Formacion!$F:$F,0)) -> -20630 | D40: =INDEX(C4_Formacion!$H:$H,MATCH(A40&"(g)",C4_Formacion!$F:$F,0)) -> -33560 | E40: =INDEX(C1_Gases!$K:$K,MATCH($A40,C1_Gases!$D:$D,0)) -> 3.931 | F40: =INDEX(C1_Gases!$L:$L,MATCH($A40,C1_Gases!$D:$D,0)) -> 0.00149 | G40: =INDEX(C1_Gases!$M:$M,MATCH($A40,C1_Gases!$D:$D,0)) -> 0 | H40: =INDEX(C1_Gases!$N:$N,MATCH($A40,C1_Gases!$D:$D,0)) -> -23200 | I40: =INDEX(C1_Gases!$E:$E,MATCH($A40,C1_Gases!$D:$D,0)) -> 2300 | J40: =INDEX(C1_Gases!$F:$F,MATCH($A40,C1_Gases!$D:$D,0)) -> 4.114 | K40: Tabla C.4 (g)
A41: HCl | B41: Cloruro de hidrógeno | C41: =INDEX(C4_Formacion!$G:$G,MATCH(A41&"(g)",C4_Formacion!$F:$F,0)) -> -92307 | D41: =INDEX(C4_Formacion!$H:$H,MATCH(A41&"(g)",C4_Formacion!$F:$F,0)) -> -95299 | E41: =INDEX(C1_Gases!$K:$K,MATCH($A41,C1_Gases!$D:$D,0)) -> 3.156 | F41: =INDEX(C1_Gases!$L:$L,MATCH($A41,C1_Gases!$D:$D,0)) -> 0.000623 | G41: =INDEX(C1_Gases!$M:$M,MATCH($A41,C1_Gases!$D:$D,0)) -> 0 | H41: =INDEX(C1_Gases!$N:$N,MATCH($A41,C1_Gases!$D:$D,0)) -> 15100 | I41: =INDEX(C1_Gases!$E:$E,MATCH($A41,C1_Gases!$D:$D,0)) -> 2000 | J41: =INDEX(C1_Gases!$F:$F,MATCH($A41,C1_Gases!$D:$D,0)) -> 3.512 | K41: Tabla C.4 (g)
...

Sheet Buscar
A1: Buscar propiedades de una especie
A2: Escribe la fórmula exactamente como en BD_Gases (p. ej. CH4, H2O, C4H10 (iso)) en la celda amarilla.
A4: Fórmula: | B4: CH4
A6: Especie | B6: =IFERROR(INDEX(BD_Gases!$B:$B,MATCH($B$4,BD_Gases!$A:$A,0)),"no está") -> Metano
A7: ΔH°f298 /J·mol⁻¹ | B7: =IFERROR(INDEX(BD_Gases!$C:$C,MATCH($B$4,BD_Gases!$A:$A,0)),"no está") -> -74520
A8: ΔG°f298 /J·mol⁻¹ | B8: =IFERROR(INDEX(BD_Gases!$D:$D,MATCH($B$4,BD_Gases!$A:$A,0)),"no está") -> -50460
A9: A | B9: =IFERROR(INDEX(BD_Gases!$E:$E,MATCH($B$4,BD_Gases!$A:$A,0)),"no está") -> 1.702
A10: B | B10: =IFERROR(INDEX(BD_Gases!$F:$F,MATCH($B$4,BD_Gases!$A:$A,0)),"no está") -> 0.009081
A11: C | B11: =IFERROR(INDEX(BD_Gases!$G:$G,MATCH($B$4,BD_Gases!$A:$A,0)),"no está") -> -2.164e-06
A12: D | B12: =IFERROR(INDEX(BD_Gases!$H:$H,MATCH($B$4,BD_Gases!$A:$A,0)),"no está") -> 0
A13: Tmáx /K | B13: =IFERROR(INDEX(BD_Gases!$I:$I,MATCH($B$4,BD_Gases!$A:$A,0)),"no está") -> 1500
A14: Cp298/R | B14: =IFERROR(INDEX(BD_Gases!$J:$J,MATCH($B$4,BD_Gases!$A:$A,0)),"no está") -> 4.217
A16: T /K: | B16: 800
A17: Cp/R a T | B17: =B9+B10*B16+B11*B16^2+B12/B16^2 -> 7.58184
A18: Cp /J·mol⁻¹·K⁻¹ | B18: =8.314*B17 -> 63.035418
A19: Aviso Tmáx | B19: =IF(B16>B13,"T > Tmáx: fuera del rango de la correlación","OK") -> OK
